<?xml version="1.0" ?>
<!-- =================================================================================== -->
<!-- |    This document was autogenerated by xacro from /home/fynnb/spz_ws/src/TDF-mobile-manipulator-simulation/butler_robot/urdf/butler_robot.urdf.xacro | -->
<!-- |    EDITING THIS FILE BY HAND IS NOT RECOMMENDED                                 | -->
<!-- =================================================================================== -->
<!-- Build the complete robot of common-stuff, mir, ur, controlbox and eef. Loads all components and connects them -->
<robot name="butler_robot">
    <!-- This file is only for backward compatibility before the "mir_100" to "mir" rename. -->
    <!-- necessary because args cannot be accessed inside ${} expressions -->
    <link name="base_footprint" />
    <joint name="base_joint" type="fixed">
        <parent link="base_footprint" />
        <child link="base_link" />
        <origin rpy="0 0 0" xyz="0 0 0" />
    </joint>
    <link name="base_link">
        <inertial>
            <mass value="77.0" />
            <origin rpy="0 0 0" xyz="-0.012354000000000004 0.0 0.15" />
            <inertia ixx="0.8341663330000001" ixy="0.0" ixz="0.0" iyy="1.8608325890000004" iyz="0.0" izz="2.1816657939999997" />
        </inertial>
        <visual>
            <origin rpy="0 0 0" xyz="0.037646 0 0" />
            <geometry>
                <mesh filename="package://mir_description/meshes/visual/mir_100_base.stl" />
            </geometry>
            <material name="white">
                <color rgba="1 1 1 1" />
            </material>
        </visual>
        <collision>
            <origin rpy="0 0 0" xyz="0.037646 0 0" />
            <geometry>
                <mesh filename="package://mir_description/meshes/collision/mir_100_base.stl" />
            </geometry>
        </collision>
    </link>
    <gazebo reference="base_link">
        <material>Gazebo/White</material>
        <plugin name="gazebo_ros_control">
            <robotNamespace>/</robotNamespace>
        </plugin>
    </gazebo>
    <!-- IMU -->
    <joint name="base_link_to_imu_joint" type="fixed">
        <parent link="base_link" />
        <child link="imu_link" />
        <origin rpy="0 0 0" xyz="0.0 0.0 0.25" />
        <!-- same as real MiR -->
    </joint>
    <link name="imu_link" />
    <gazebo>
        <plugin filename="libhector_gazebo_ros_imu.so" name="imu_plugin">
            <updateRate>50.0</updateRate>
            <bodyName>imu_link</bodyName>
            <frameId>imu_frame</frameId>
            <!-- from real MiR -->
            <topicName>imu_data</topicName>
            <accelDrift>0.0 0.0 0.0</accelDrift>
            <accelGaussianNoise>0.007071067811865475 0.01 0.011401754250991379</accelGaussianNoise>
            <!-- real MiR linear_acceleration_covariance: [5e-05, 0.0, 0.0, 0.0, 0.0001, 0.0, 0.0, 0.0, 0.00013] -->
            <rateDrift>0.0 0.0 0.0</rateDrift>
            <rateGaussianNoise>0.00282842712474619 0.00282842712474619 0.0005477225575051661</rateGaussianNoise>
            <!-- real MiR angular_velocity_covariance: [8e-06, 0.0, 0.0, 0.0, 8e-06, 0.0, 0.0, 0.0, 3e-07] -->
            <yawDrift>0.0</yawDrift>
            <yawGaussianNoise>0.31622776601683794</yawGaussianNoise>
            <!-- real MiR orientation_covariance: [0.1, 0.0, 0.0, 0.0, 0.1, 0.0, 0.0, 0.0, 0.1] -->
        </plugin>
    </gazebo>
    <!-- Create an alias for imu_link. This is necessary because the real MiR's
         TF has imu_link, but the imu_data topic is published in the imu_frame
         frame. -->
    <joint name="imu_link_to_imu_frame_joint" type="fixed">
        <parent link="imu_link" />
        <child link="imu_frame" />
        <origin rpy="0 0 0" xyz="0 0 0" />
    </joint>
    <link name="imu_frame" />
    <!-- Laser scanners -->
    <joint name="base_link_to_front_laser_joint" type="fixed">
        <parent link="base_link" />
        <child link="front_laser_link" />
        <origin rpy="0.0 0.0 0.7853981633974483" xyz="0.42964600000000003 0.2358 0.1914" />
    </joint>
    <link name="front_laser_link">
        <visual>
            <origin rpy="3.141592653589793 0 0" xyz="0.0 0.0 0.0" />
            <geometry>
                <mesh filename="package://mir_description/meshes/visual/sick_lms-100.stl" />
            </geometry>
            <!-- <xacro:insert_block name="material_yellow" /> -->
            <material name="black">
                <color rgba="0.1 0.1 0.1 1" />
            </material>
        </visual>
        <collision>
            <origin rpy="3.141592653589793 0 0" xyz="0.0 0.0 0.0" />
            <geometry>
                <mesh filename="package://mir_description/meshes/visual/sick_lms-100.stl" />
            </geometry>
        </collision>
        <inertial>
            <mass value="1.2" />
            <origin xyz="0 0 0" rpy="0 0 0" />
            <inertia ixx="0.005824997669999999" ixy="0.0" ixz="0.0" iyy="0.00585609765756" iyz="0.0" izz="0.00483609806556" />
        </inertial>
    </link>
    <gazebo reference="front_laser_link">
        <!-- <material value="Gazebo/Yellow" /> -->
        <material value="Gazebo/FlatBlack" />
        <sensor name="front_laser_link" type="ray">
            <pose>0 0 0 0 0 0</pose>
            <visualize>false</visualize>
            <update_rate>12.5</update_rate>
            <ray>
                <scan>
                    <horizontal>
                        <samples>541</samples>
                        <resolution>1</resolution>
                        <!-- has to be 1; actual resolution will be computed from number of samples + min_angle/max_angle -->
                        <min_angle>-2.35619449615</min_angle>
                        <max_angle>2.35619449615</max_angle>
                    </horizontal>
                </scan>
                <range>
                    <min>0.05</min>
                    <max>29.0</max>
                    <resolution>0.01</resolution>
                </range>
                <noise>
                    <type>gaussian</type>
                    <!-- Noise parameters based on published spec for S300 achieving
                 "+-29mm" accuracy at range < 3m (~0.01 of the range) at
                 1 sigma. -->
                    <mean>0.0</mean>
                    <stddev>0.01</stddev>
                </noise>
            </ray>
            <plugin filename="libgazebo_ros_laser.so" name="gazebo_ros_front_laser_link_controller">
                <frameName>front_laser_link</frameName>
                <topicName>f_scan</topicName>
            </plugin>
        </sensor>
    </gazebo>
    <joint name="base_link_to_back_laser_joint" type="fixed">
        <parent link="base_link" />
        <child link="back_laser_link" />
        <origin rpy="0.0 0.0 -2.356194490192345" xyz="-0.354354 -0.2358 0.1914" />
    </joint>
    <link name="back_laser_link">
        <visual>
            <origin rpy="3.141592653589793 0 0" xyz="0.0 0.0 0.0" />
            <geometry>
                <mesh filename="package://mir_description/meshes/visual/sick_lms-100.stl" />
            </geometry>
            <!-- <xacro:insert_block name="material_yellow" /> -->
            <material name="black">
                <color rgba="0.1 0.1 0.1 1" />
            </material>
        </visual>
        <collision>
            <origin rpy="3.141592653589793 0 0" xyz="0.0 0.0 0.0" />
            <geometry>
                <mesh filename="package://mir_description/meshes/visual/sick_lms-100.stl" />
            </geometry>
        </collision>
        <inertial>
            <mass value="1.2" />
            <origin xyz="0 0 0" rpy="0 0 0" />
            <inertia ixx="0.005824997669999999" ixy="0.0" ixz="0.0" iyy="0.00585609765756" iyz="0.0" izz="0.00483609806556" />
        </inertial>
    </link>
    <gazebo reference="back_laser_link">
        <!-- <material value="Gazebo/Yellow" /> -->
        <material value="Gazebo/FlatBlack" />
        <sensor name="back_laser_link" type="ray">
            <pose>0 0 0 0 0 0</pose>
            <visualize>false</visualize>
            <update_rate>12.5</update_rate>
            <ray>
                <scan>
                    <horizontal>
                        <samples>541</samples>
                        <resolution>1</resolution>
                        <!-- has to be 1; actual resolution will be computed from number of samples + min_angle/max_angle -->
                        <min_angle>-2.35619449615</min_angle>
                        <max_angle>2.35619449615</max_angle>
                    </horizontal>
                </scan>
                <range>
                    <min>0.05</min>
                    <max>29.0</max>
                    <resolution>0.01</resolution>
                </range>
                <noise>
                    <type>gaussian</type>
                    <!-- Noise parameters based on published spec for S300 achieving
                 "+-29mm" accuracy at range < 3m (~0.01 of the range) at
                 1 sigma. -->
                    <mean>0.0</mean>
                    <stddev>0.01</stddev>
                </noise>
            </ray>
            <plugin filename="libgazebo_ros_laser.so" name="gazebo_ros_back_laser_link_controller">
                <frameName>back_laser_link</frameName>
                <topicName>b_scan</topicName>
            </plugin>
        </sensor>
    </gazebo>
    <!-- Ultrasound sensors -->
    <joint name="us_1_joint" type="fixed">
        <!-- right ultrasound -->
        <parent link="base_link" />
        <child link="us_1_frame" />
        <origin rpy="0 0 0" xyz="0.45 -0.12 0.16 " />
        <!-- from visually matching to the mesh of the MiR -->
    </joint>
    <link name="us_1_frame" />
    <joint name="us_2_joint" type="fixed">
        <!-- left ultrasound -->
        <parent link="base_link" />
        <child link="us_2_frame" />
        <origin rpy="0 0 0" xyz="0.45 0.12 0.16 " />
        <!-- from visually matching to the mesh of the MiR -->
    </joint>
    <link name="us_2_frame" />
    <joint name="left_wheel_joint" type="continuous">
        <origin rpy="0 0 0" xyz="0.0 0.222604 0.0625" />
        <parent link="base_link" />
        <child link="left_wheel_link" />
        <axis xyz="0 1 0" />
        <limit effort="100" velocity="20.0" />
    </joint>
    <link name="left_wheel_link">
        <inertial>
            <mass value="1.0" />
            <origin rpy="1.5707963267948966 0 0" xyz="0 0 0" />
            <inertia ixx="0.001061895408575" ixy="0.0" ixz="0.0" iyy="0.001061895408575" iyz="0.0" izz="0.001953125" />
        </inertial>
        <visual>
            <origin rpy="1.5707963267948966 0 0" xyz="0 0 0" />
            <geometry>
                <cylinder length="0.032" radius="0.0625" />
            </geometry>
            <material name="black">
                <color rgba="0.1 0.1 0.1 1" />
            </material>
        </visual>
        <collision>
            <origin rpy="1.5707963267948966 0 0" xyz="0 0 0" />
            <geometry>
                <cylinder length="0.032" radius="0.0625" />
            </geometry>
        </collision>
    </link>
    <gazebo reference="left_wheel_link">
        <material>Gazebo/FlatBlack</material>
    </gazebo>
    <joint name="right_wheel_joint" type="continuous">
        <origin rpy="0 0 0" xyz="0.0 -0.222604 0.0625" />
        <parent link="base_link" />
        <child link="right_wheel_link" />
        <axis xyz="0 1 0" />
        <limit effort="100" velocity="20.0" />
    </joint>
    <link name="right_wheel_link">
        <inertial>
            <mass value="1.0" />
            <origin rpy="1.5707963267948966 0 0" xyz="0 0 0" />
            <inertia ixx="0.001061895408575" ixy="0.0" ixz="0.0" iyy="0.001061895408575" iyz="0.0" izz="0.001953125" />
        </inertial>
        <visual>
            <origin rpy="1.5707963267948966 0 0" xyz="0 0 0" />
            <geometry>
                <cylinder length="0.032" radius="0.0625" />
            </geometry>
            <material name="black">
                <color rgba="0.1 0.1 0.1 1" />
            </material>
        </visual>
        <collision>
            <origin rpy="1.5707963267948966 0 0" xyz="0 0 0" />
            <geometry>
                <cylinder length="0.032" radius="0.0625" />
            </geometry>
        </collision>
    </link>
    <gazebo reference="right_wheel_link">
        <material>Gazebo/FlatBlack</material>
    </gazebo>
    <!-- caster hub -->
    <joint name="fl_caster_rotation_joint" type="continuous">
        <origin rpy="0 0 0" xyz="0.34134600000000004 0.203 0.1565" />
        <parent link="base_link" />
        <child link="fl_caster_rotation_link" />
        <axis xyz="0 0 1" />
        <dynamics damping="0.01" friction="0.0" />
    </joint>
    <link name="fl_caster_rotation_link">
        <inertial>
            <!-- <origin xyz="0 0 -0.042500000044" rpy="${0.5 * pi} ${24 * deg_to_rad} ${1.5 * pi}" /> -->
            <origin rpy="0.41887903200000004 0 1.5707963267948966 " xyz="0 0 -0.042500000044" />
            <mass value="0.3097539019" />
            <inertia ixx="0.0005844517978" ixy="0" ixz="0" iyy="0.00052872551237" iyz="0" izz="0.00017923555074" />
        </inertial>
        <visual>
            <origin rpy="0 0 0" xyz="0 0 0" />
            <geometry>
                <mesh filename="package://mir_description/meshes/visual/caster_wheel_base.stl" />
            </geometry>
            <material name="silver">
                <color rgba="0.79 0.82 0.93 1" />
            </material>
        </visual>
        <collision>
            <origin rpy="0 0 0" xyz="0 0 0" />
            <geometry>
                <mesh filename="package://mir_description/meshes/collision/caster_wheel_base.stl" />
            </geometry>
        </collision>
    </link>
    <gazebo reference="fl_caster_rotation_link">
        <material>Gazebo/Grey</material>
    </gazebo>
    <!-- caster wheel -->
    <joint name="fl_caster_wheel_joint" type="continuous">
        <origin rpy="0 0 0" xyz="-0.0382 0 -0.094" />
        <parent link="fl_caster_rotation_link" />
        <child link="fl_caster_wheel_link" />
        <axis xyz="0 1 0" />
    </joint>
    <link name="fl_caster_wheel_link">
        <inertial>
            <mass value="1.0" />
            <origin rpy="1.5707963267948966 0 0" xyz="0 0 0" />
            <inertia ixx="0.001061895408575" ixy="0.0" ixz="0.0" iyy="0.001061895408575" iyz="0.0" izz="0.001953125" />
        </inertial>
        <visual>
            <origin rpy="1.5707963267948966 0 0" xyz="0 0 0" />
            <geometry>
                <cylinder length="0.032" radius="0.0625" />
            </geometry>
            <material name="black">
                <color rgba="0.1 0.1 0.1 1" />
            </material>
        </visual>
        <collision>
            <origin rpy="1.5707963267948966 0 0" xyz="0 0 0" />
            <geometry>
                <cylinder length="0.032" radius="0.0625" />
            </geometry>
        </collision>
    </link>
    <gazebo reference="fl_caster_wheel_link">
        <material>Gazebo/FlatBlack</material>
    </gazebo>
    <!-- caster hub -->
    <joint name="fr_caster_rotation_joint" type="continuous">
        <origin rpy="0 0 0" xyz="0.34134600000000004 -0.203 0.1565" />
        <parent link="base_link" />
        <child link="fr_caster_rotation_link" />
        <axis xyz="0 0 1" />
        <dynamics damping="0.01" friction="0.0" />
    </joint>
    <link name="fr_caster_rotation_link">
        <inertial>
            <!-- <origin xyz="0 0 -0.042500000044" rpy="${0.5 * pi} ${24 * deg_to_rad} ${1.5 * pi}" /> -->
            <origin rpy="0.41887903200000004 0 1.5707963267948966 " xyz="0 0 -0.042500000044" />
            <mass value="0.3097539019" />
            <inertia ixx="0.0005844517978" ixy="0" ixz="0" iyy="0.00052872551237" iyz="0" izz="0.00017923555074" />
        </inertial>
        <visual>
            <origin rpy="0 0 0" xyz="0 0 0" />
            <geometry>
                <mesh filename="package://mir_description/meshes/visual/caster_wheel_base.stl" />
            </geometry>
            <material name="silver">
                <color rgba="0.79 0.82 0.93 1" />
            </material>
        </visual>
        <collision>
            <origin rpy="0 0 0" xyz="0 0 0" />
            <geometry>
                <mesh filename="package://mir_description/meshes/collision/caster_wheel_base.stl" />
            </geometry>
        </collision>
    </link>
    <gazebo reference="fr_caster_rotation_link">
        <material>Gazebo/Grey</material>
    </gazebo>
    <!-- caster wheel -->
    <joint name="fr_caster_wheel_joint" type="continuous">
        <origin rpy="0 0 0" xyz="-0.0382 0 -0.094" />
        <parent link="fr_caster_rotation_link" />
        <child link="fr_caster_wheel_link" />
        <axis xyz="0 1 0" />
    </joint>
    <link name="fr_caster_wheel_link">
        <inertial>
            <mass value="1.0" />
            <origin rpy="1.5707963267948966 0 0" xyz="0 0 0" />
            <inertia ixx="0.001061895408575" ixy="0.0" ixz="0.0" iyy="0.001061895408575" iyz="0.0" izz="0.001953125" />
        </inertial>
        <visual>
            <origin rpy="1.5707963267948966 0 0" xyz="0 0 0" />
            <geometry>
                <cylinder length="0.032" radius="0.0625" />
            </geometry>
            <material name="black">
                <color rgba="0.1 0.1 0.1 1" />
            </material>
        </visual>
        <collision>
            <origin rpy="1.5707963267948966 0 0" xyz="0 0 0" />
            <geometry>
                <cylinder length="0.032" radius="0.0625" />
            </geometry>
        </collision>
    </link>
    <gazebo reference="fr_caster_wheel_link">
        <material>Gazebo/FlatBlack</material>
    </gazebo>
    <!-- caster hub -->
    <joint name="bl_caster_rotation_joint" type="continuous">
        <origin rpy="0 0 0" xyz="-0.270154 0.203 0.1565" />
        <parent link="base_link" />
        <child link="bl_caster_rotation_link" />
        <axis xyz="0 0 1" />
        <dynamics damping="0.01" friction="0.0" />
    </joint>
    <link name="bl_caster_rotation_link">
        <inertial>
            <!-- <origin xyz="0 0 -0.042500000044" rpy="${0.5 * pi} ${24 * deg_to_rad} ${1.5 * pi}" /> -->
            <origin rpy="0.41887903200000004 0 1.5707963267948966 " xyz="0 0 -0.042500000044" />
            <mass value="0.3097539019" />
            <inertia ixx="0.0005844517978" ixy="0" ixz="0" iyy="0.00052872551237" iyz="0" izz="0.00017923555074" />
        </inertial>
        <visual>
            <origin rpy="0 0 0" xyz="0 0 0" />
            <geometry>
                <mesh filename="package://mir_description/meshes/visual/caster_wheel_base.stl" />
            </geometry>
            <material name="silver">
                <color rgba="0.79 0.82 0.93 1" />
            </material>
        </visual>
        <collision>
            <origin rpy="0 0 0" xyz="0 0 0" />
            <geometry>
                <mesh filename="package://mir_description/meshes/collision/caster_wheel_base.stl" />
            </geometry>
        </collision>
    </link>
    <gazebo reference="bl_caster_rotation_link">
        <material>Gazebo/Grey</material>
    </gazebo>
    <!-- caster wheel -->
    <joint name="bl_caster_wheel_joint" type="continuous">
        <origin rpy="0 0 0" xyz="-0.0382 0 -0.094" />
        <parent link="bl_caster_rotation_link" />
        <child link="bl_caster_wheel_link" />
        <axis xyz="0 1 0" />
    </joint>
    <link name="bl_caster_wheel_link">
        <inertial>
            <mass value="1.0" />
            <origin rpy="1.5707963267948966 0 0" xyz="0 0 0" />
            <inertia ixx="0.001061895408575" ixy="0.0" ixz="0.0" iyy="0.001061895408575" iyz="0.0" izz="0.001953125" />
        </inertial>
        <visual>
            <origin rpy="1.5707963267948966 0 0" xyz="0 0 0" />
            <geometry>
                <cylinder length="0.032" radius="0.0625" />
            </geometry>
            <material name="black">
                <color rgba="0.1 0.1 0.1 1" />
            </material>
        </visual>
        <collision>
            <origin rpy="1.5707963267948966 0 0" xyz="0 0 0" />
            <geometry>
                <cylinder length="0.032" radius="0.0625" />
            </geometry>
        </collision>
    </link>
    <gazebo reference="bl_caster_wheel_link">
        <material>Gazebo/FlatBlack</material>
    </gazebo>
    <!-- caster hub -->
    <joint name="br_caster_rotation_joint" type="continuous">
        <origin rpy="0 0 0" xyz="-0.270154 -0.203 0.1565" />
        <parent link="base_link" />
        <child link="br_caster_rotation_link" />
        <axis xyz="0 0 1" />
        <dynamics damping="0.01" friction="0.0" />
    </joint>
    <link name="br_caster_rotation_link">
        <inertial>
            <!-- <origin xyz="0 0 -0.042500000044" rpy="${0.5 * pi} ${24 * deg_to_rad} ${1.5 * pi}" /> -->
            <origin rpy="0.41887903200000004 0 1.5707963267948966 " xyz="0 0 -0.042500000044" />
            <mass value="0.3097539019" />
            <inertia ixx="0.0005844517978" ixy="0" ixz="0" iyy="0.00052872551237" iyz="0" izz="0.00017923555074" />
        </inertial>
        <visual>
            <origin rpy="0 0 0" xyz="0 0 0" />
            <geometry>
                <mesh filename="package://mir_description/meshes/visual/caster_wheel_base.stl" />
            </geometry>
            <material name="silver">
                <color rgba="0.79 0.82 0.93 1" />
            </material>
        </visual>
        <collision>
            <origin rpy="0 0 0" xyz="0 0 0" />
            <geometry>
                <mesh filename="package://mir_description/meshes/collision/caster_wheel_base.stl" />
            </geometry>
        </collision>
    </link>
    <gazebo reference="br_caster_rotation_link">
        <material>Gazebo/Grey</material>
    </gazebo>
    <!-- caster wheel -->
    <joint name="br_caster_wheel_joint" type="continuous">
        <origin rpy="0 0 0" xyz="-0.0382 0 -0.094" />
        <parent link="br_caster_rotation_link" />
        <child link="br_caster_wheel_link" />
        <axis xyz="0 1 0" />
    </joint>
    <link name="br_caster_wheel_link">
        <inertial>
            <mass value="1.0" />
            <origin rpy="1.5707963267948966 0 0" xyz="0 0 0" />
            <inertia ixx="0.001061895408575" ixy="0.0" ixz="0.0" iyy="0.001061895408575" iyz="0.0" izz="0.001953125" />
        </inertial>
        <visual>
            <origin rpy="1.5707963267948966 0 0" xyz="0 0 0" />
            <geometry>
                <cylinder length="0.032" radius="0.0625" />
            </geometry>
            <material name="black">
                <color rgba="0.1 0.1 0.1 1" />
            </material>
        </visual>
        <collision>
            <origin rpy="1.5707963267948966 0 0" xyz="0 0 0" />
            <geometry>
                <cylinder length="0.032" radius="0.0625" />
            </geometry>
        </collision>
    </link>
    <gazebo reference="br_caster_wheel_link">
        <material>Gazebo/FlatBlack</material>
    </gazebo>
    <joint name="base_link_surface_joint" type="fixed">
        <origin rpy="0 0 0" xyz="0.037646 0 0.352" />
        <parent link="base_link" />
        <child link="surface" />
        <axis xyz="0 0 1" />
    </joint>
    <link name="surface" />
    <transmission name="left_wheel_trans">
        <type>transmission_interface/SimpleTransmission</type>
        <joint name="left_wheel_joint">
            <hardwareInterface>hardware_interface/VelocityJointInterface</hardwareInterface>
        </joint>
        <actuator name="left_wheel_motor">
            <hardwareInterface>hardware_interface/VelocityJointInterface</hardwareInterface>
            <mechanicalReduction>1</mechanicalReduction>
        </actuator>
    </transmission>
    <transmission name="right_wheel_trans">
        <type>transmission_interface/SimpleTransmission</type>
        <joint name="right_wheel_joint">
            <hardwareInterface>hardware_interface/VelocityJointInterface</hardwareInterface>
        </joint>
        <actuator name="right_wheel_motor">
            <hardwareInterface>hardware_interface/VelocityJointInterface</hardwareInterface>
            <mechanicalReduction>1</mechanicalReduction>
        </actuator>
    </transmission>
    <gazebo reference="left_wheel_link">
        <mu1 value="200" />
        <mu2 value="200" />
        <kp value="10000000.0" />
        <kd value="1.0" />
        <minDepth>0.01</minDepth>
    </gazebo>
    <gazebo reference="right_wheel_link">
        <mu1 value="200" />
        <mu2 value="200" />
        <kp value="10000000.0" />
        <kd value="1.0" />
        <minDepth>0.01</minDepth>
    </gazebo>
    <gazebo reference="fl_caster_wheel_link">
        <mu1 value="1" />
        <mu2 value="1" />
        <kp value="10000000.0" />
        <kd value="1.0" />
        <minDepth>0.01</minDepth>
    </gazebo>
    <gazebo reference="fr_caster_wheel_link">
        <mu1 value="1" />
        <mu2 value="1" />
        <kp value="10000000.0" />
        <kd value="1.0" />
        <minDepth>0.01</minDepth>
    </gazebo>
    <gazebo reference="bl_caster_wheel_link">
        <mu1 value="1" />
        <mu2 value="1" />
        <kp value="10000000.0" />
        <kd value="1.0" />
        <minDepth>0.01</minDepth>
    </gazebo>
    <gazebo reference="br_caster_wheel_link">
        <mu1 value="1" />
        <mu2 value="1" />
        <kp value="10000000.0" />
        <kd value="1.0" />
        <minDepth>0.01</minDepth>
    </gazebo>
    <gazebo>
        <plugin filename="libgazebo_ros_p3d.so" name="p3d_base_controller">
            <alwaysOn>true</alwaysOn>
            <updateRate>50.0</updateRate>
            <bodyName>base_footprint</bodyName>
            <topicName>base_pose_ground_truth</topicName>
            <gaussianNoise>0.01</gaussianNoise>
            <frameName>map</frameName>
            <xyzOffsets>0 0 0</xyzOffsets>
            <rpyOffsets>0 0 0</rpyOffsets>
        </plugin>
    </gazebo>
    <gazebo>
        <plugin filename="libgazebo_ros_control.so" name="gazebo_ros_control">
            <controlPeriod>0.001</controlPeriod>
            <legacyModeNS>false</legacyModeNS>
        </plugin>
    </gazebo>
    <!--
    Base UR robot series xacro macro.

    NOTE: this is NOT a URDF. It cannot directly be loaded by consumers
    expecting a flattened '.urdf' file. See the top-level '.xacro' for that
    (but note: that .xacro must still be processed by the xacro command).

    For use in '.launch' files: use one of the 'load_urX.launch' convenience
    launch files.

    This file models the base kinematic chain of a UR robot, which then gets
    parameterised by various configuration files to convert it into a UR3(e),
    UR5(e), UR10(e) or UR16e.

    NOTE: the default kinematic parameters (ie: link lengths, frame locations,
    offets, etc) do not correspond to any particular robot. They are defaults
    only. There WILL be non-zero offsets between the Forward Kinematics results
    in TF (ie: robot_state_publisher) and the values reported by the Teach
    Pendant.

    For accurate (and robot-specific) transforms, the 'kinematics_parameters_file'
    parameter MUST point to a .yaml file containing the appropriate values for
    the targetted robot.

    If using the UniversalRobots/Universal_Robots_ROS_Driver, follow the steps
    described in the readme of that repository to extract the kinematic
    calibration from the controller and generate the required .yaml file.

    Main author of the migration to yaml configs: Ludovic Delval.

    Contributors to previous versions (in no particular order):

     - Felix Messmer
     - Kelsey Hawkins
     - Wim Meeussen
     - Shaun Edwards
     - Nadia Hammoudeh Garcia
     - Dave Hershberger
     - G. vd. Hoorn
     - Philip Long
     - Dave Coleman
     - Miguel Prada
     - Mathias Luedtke
     - Marcel Schnirring
     - Felix von Drigalski
     - Felix Exner
     - Jimmy Da Silva
     - Ajit Krisshna N L
     - Muhammad Asif Rana
  -->
    <!--
    NOTE: the macro defined in this file is NOT part of the public API of this
          package. Users CANNOT rely on this file being available, or stored in
          this location. Nor can they rely on the existence of the macro.
  -->
    <transmission name="ur_shoulder_pan_trans">
        <type>transmission_interface/SimpleTransmission</type>
        <joint name="ur_shoulder_pan_joint">
            <hardwareInterface>hardware_interface/PositionJointInterface</hardwareInterface>
        </joint>
        <actuator name="ur_shoulder_pan_motor">
            <mechanicalReduction>1</mechanicalReduction>
            <hardwareInterface>hardware_interface/PositionJointInterface</hardwareInterface>
        </actuator>
    </transmission>
    <transmission name="ur_shoulder_lift_trans">
        <type>transmission_interface/SimpleTransmission</type>
        <joint name="ur_shoulder_lift_joint">
            <hardwareInterface>hardware_interface/PositionJointInterface</hardwareInterface>
        </joint>
        <actuator name="ur_shoulder_lift_motor">
            <mechanicalReduction>1</mechanicalReduction>
            <hardwareInterface>hardware_interface/PositionJointInterface</hardwareInterface>
        </actuator>
    </transmission>
    <transmission name="ur_elbow_trans">
        <type>transmission_interface/SimpleTransmission</type>
        <joint name="ur_elbow_joint">
            <hardwareInterface>hardware_interface/PositionJointInterface</hardwareInterface>
        </joint>
        <actuator name="ur_elbow_motor">
            <mechanicalReduction>1</mechanicalReduction>
            <hardwareInterface>hardware_interface/PositionJointInterface</hardwareInterface>
        </actuator>
    </transmission>
    <transmission name="ur_wrist_1_trans">
        <type>transmission_interface/SimpleTransmission</type>
        <joint name="ur_wrist_1_joint">
            <hardwareInterface>hardware_interface/PositionJointInterface</hardwareInterface>
        </joint>
        <actuator name="ur_wrist_1_motor">
            <mechanicalReduction>1</mechanicalReduction>
            <hardwareInterface>hardware_interface/PositionJointInterface</hardwareInterface>
        </actuator>
    </transmission>
    <transmission name="ur_wrist_2_trans">
        <type>transmission_interface/SimpleTransmission</type>
        <joint name="ur_wrist_2_joint">
            <hardwareInterface>hardware_interface/PositionJointInterface</hardwareInterface>
        </joint>
        <actuator name="ur_wrist_2_motor">
            <mechanicalReduction>1</mechanicalReduction>
            <hardwareInterface>hardware_interface/PositionJointInterface</hardwareInterface>
        </actuator>
    </transmission>
    <transmission name="ur_wrist_3_trans">
        <type>transmission_interface/SimpleTransmission</type>
        <joint name="ur_wrist_3_joint">
            <hardwareInterface>hardware_interface/PositionJointInterface</hardwareInterface>
        </joint>
        <actuator name="ur_wrist_3_motor">
            <mechanicalReduction>1</mechanicalReduction>
            <hardwareInterface>hardware_interface/PositionJointInterface</hardwareInterface>
        </actuator>
    </transmission>
    <!-- links: main serial chain -->
    <link name="ur_base_link" />
    <link name="ur_base_link_inertia">
        <visual>
            <origin rpy="0 0 3.141592653589793" xyz="0 0 0" />
            <geometry>
                <mesh filename="package://ur_description/meshes/ur5/visual/base.dae" />
            </geometry>
            <material name="LightGrey">
                <color rgba="0.7 0.7 0.7 1.0" />
            </material>
        </visual>
        <collision>
            <origin rpy="0 0 3.141592653589793" xyz="0 0 0" />
            <geometry>
                <mesh filename="package://ur_description/meshes/ur5/collision/base.stl" />
            </geometry>
        </collision>
        <inertial>
            <mass value="4.0" />
            <origin rpy="0 0 0" xyz="0 0 0" />
            <inertia ixx="0.00443333156" ixy="0.0" ixz="0.0" iyy="0.00443333156" iyz="0.0" izz="0.0072" />
        </inertial>
    </link>
    <link name="ur_shoulder_link">
        <visual>
            <origin rpy="0 0 3.141592653589793" xyz="0 0 0" />
            <geometry>
                <mesh filename="package://ur_description/meshes/ur5/visual/shoulder.dae" />
            </geometry>
            <material name="LightGrey">
                <color rgba="0.7 0.7 0.7 1.0" />
            </material>
        </visual>
        <collision>
            <origin rpy="0 0 3.141592653589793" xyz="0 0 0" />
            <geometry>
                <mesh filename="package://ur_description/meshes/ur5/collision/shoulder.stl" />
            </geometry>
        </collision>
        <inertial>
            <mass value="3.7" />
            <origin rpy="0 0 0" xyz="0 0 0" />
            <inertia ixx="0.014972352344389999" ixy="0.0" ixz="0.0" iyy="0.014972352344389999" iyz="0.0" izz="0.01040625" />
        </inertial>
    </link>
    <link name="ur_upper_arm_link">
        <visual>
            <origin rpy="1.5707963267948966 0 -1.5707963267948966" xyz="0 0 0.13585" />
            <geometry>
                <mesh filename="package://ur_description/meshes/ur5/visual/upperarm.dae" />
            </geometry>
            <material name="LightGrey">
                <color rgba="0.7 0.7 0.7 1.0" />
            </material>
        </visual>
        <collision>
            <origin rpy="1.5707963267948966 0 -1.5707963267948966" xyz="0 0 0.13585" />
            <geometry>
                <mesh filename="package://ur_description/meshes/ur5/collision/upperarm.stl" />
            </geometry>
        </collision>
        <inertial>
            <mass value="8.393" />
            <origin rpy="0 1.5707963267948966 0" xyz="-0.2125 0.0 0.136" />
            <inertia ixx="0.1338857818623325" ixy="0.0" ixz="0.0" iyy="0.1338857818623325" iyz="0.0" izz="0.0151074" />
        </inertial>
    </link>
    <link name="ur_forearm_link">
        <visual>
            <origin rpy="1.5707963267948966 0 -1.5707963267948966" xyz="0 0 0.0165" />
            <geometry>
                <mesh filename="package://ur_description/meshes/ur5/visual/forearm.dae" />
            </geometry>
            <material name="LightGrey">
                <color rgba="0.7 0.7 0.7 1.0" />
            </material>
        </visual>
        <collision>
            <origin rpy="1.5707963267948966 0 -1.5707963267948966" xyz="0 0 0.0165" />
            <geometry>
                <mesh filename="package://ur_description/meshes/ur5/collision/forearm.stl" />
            </geometry>
        </collision>
        <inertial>
            <mass value="2.275" />
            <origin rpy="0 1.5707963267948966 0" xyz="-0.196125 0.0 0.0165" />
            <inertia ixx="0.03121679102890359" ixy="0.0" ixz="0.0" iyy="0.03121679102890359" iyz="0.0" izz="0.004095" />
        </inertial>
    </link>
    <link name="ur_wrist_1_link">
        <visual>
            <!-- TODO: Move this to a parameter -->
            <origin rpy="1.5707963267948966 0 0" xyz="0 0 -0.093" />
            <geometry>
                <mesh filename="package://ur_description/meshes/ur5/visual/wrist1.dae" />
            </geometry>
            <material name="LightGrey">
                <color rgba="0.7 0.7 0.7 1.0" />
            </material>
        </visual>
        <collision>
            <origin rpy="1.5707963267948966 0 0" xyz="0 0 -0.093" />
            <geometry>
                <mesh filename="package://ur_description/meshes/ur5/collision/wrist1.stl" />
            </geometry>
        </collision>
        <inertial>
            <mass value="1.219" />
            <origin rpy="0 0 0" xyz="0 0 0" />
            <inertia ixx="0.0020138887777775" ixy="0.0" ixz="0.0" iyy="0.0020138887777775" iyz="0.0" izz="0.0021942" />
        </inertial>
    </link>
    <link name="ur_wrist_2_link">
        <visual>
            <origin rpy="0 0 0" xyz="0 0 -0.095" />
            <geometry>
                <mesh filename="package://ur_description/meshes/ur5/visual/wrist2.dae" />
            </geometry>
            <material name="LightGrey">
                <color rgba="0.7 0.7 0.7 1.0" />
            </material>
        </visual>
        <collision>
            <origin rpy="0 0 0" xyz="0 0 -0.095" />
            <geometry>
                <mesh filename="package://ur_description/meshes/ur5/collision/wrist2.stl" />
            </geometry>
        </collision>
        <inertial>
            <mass value="1.219" />
            <origin rpy="0 0 0" xyz="0 0 0" />
            <inertia ixx="0.0018310388509175" ixy="0.0" ixz="0.0" iyy="0.0018310388509175" iyz="0.0" izz="0.0021942" />
        </inertial>
    </link>
    <link name="ur_wrist_3_link">
        <visual>
            <origin rpy="1.5707963267948966 0 0" xyz="0 0 -0.0818" />
            <geometry>
                <mesh filename="package://ur_description/meshes/ur5/visual/wrist3.dae" />
            </geometry>
            <material name="LightGrey">
                <color rgba="0.7 0.7 0.7 1.0" />
            </material>
        </visual>
        <collision>
            <origin rpy="1.5707963267948966 0 0" xyz="0 0 -0.0818" />
            <geometry>
                <mesh filename="package://ur_description/meshes/ur5/collision/wrist3.stl" />
            </geometry>
        </collision>
        <inertial>
            <mass value="0.1879" />
            <origin rpy="0 0 0" xyz="0.0 0.0 -0.01525" />
            <inertia ixx="8.062472608343e-05" ixy="0.0" ixz="0.0" iyy="8.062472608343e-05" iyz="0.0" izz="0.0001321171875" />
        </inertial>
    </link>
    <!-- joints: main serial chain -->
    <joint name="ur_base_link-base_link_inertia" type="fixed">
        <parent link="ur_base_link" />
        <child link="ur_base_link_inertia" />
        <!-- 'base_link' is REP-103 aligned (so X+ forward), while the internal
           frames of the robot/controller have X+ pointing backwards.
           Use the joint between 'base_link' and 'base_link_inertia' (a dummy
           link/frame) to introduce the necessary rotation over Z (of pi rad).
      -->
        <origin rpy="0 0 3.141592653589793" xyz="0 0 0" />
    </joint>
    <joint name="ur_shoulder_pan_joint" type="revolute">
        <parent link="ur_base_link_inertia" />
        <child link="ur_shoulder_link" />
        <origin rpy="0 0 0" xyz="0 0 0.089159" />
        <axis xyz="0 0 1" />
        <limit effort="150.0" lower="-6.283185307179586" upper="6.283185307179586" velocity="3.141592653589793" />
        <dynamics damping="0" friction="0" />
    </joint>
    <joint name="ur_shoulder_lift_joint" type="revolute">
        <parent link="ur_shoulder_link" />
        <child link="ur_upper_arm_link" />
        <origin rpy="1.570796327 0 0" xyz="0 0 0" />
        <axis xyz="0 0 1" />
        <limit effort="150.0" lower="-6.283185307179586" upper="6.283185307179586" velocity="3.141592653589793" />
        <dynamics damping="0" friction="0" />
    </joint>
    <joint name="ur_elbow_joint" type="revolute">
        <parent link="ur_upper_arm_link" />
        <child link="ur_forearm_link" />
        <origin rpy="0 0 0" xyz="-0.425 0 0" />
        <axis xyz="0 0 1" />
        <limit effort="150.0" lower="-3.141592653589793" upper="3.141592653589793" velocity="3.141592653589793" />
        <dynamics damping="0" friction="0" />
    </joint>
    <joint name="ur_wrist_1_joint" type="revolute">
        <parent link="ur_forearm_link" />
        <child link="ur_wrist_1_link" />
        <origin rpy="0 0 0" xyz="-0.39225 0 0.10915" />
        <axis xyz="0 0 1" />
        <limit effort="28.0" lower="-6.283185307179586" upper="6.283185307179586" velocity="3.141592653589793" />
        <dynamics damping="0" friction="0" />
    </joint>
    <joint name="ur_wrist_2_joint" type="revolute">
        <parent link="ur_wrist_1_link" />
        <child link="ur_wrist_2_link" />
        <origin rpy="1.570796327 0 0" xyz="0 -0.09465 -1.941303950897609e-11" />
        <axis xyz="0 0 1" />
        <limit effort="28.0" lower="-6.283185307179586" upper="6.283185307179586" velocity="3.141592653589793" />
        <dynamics damping="0" friction="0" />
    </joint>
    <joint name="ur_wrist_3_joint" type="revolute">
        <parent link="ur_wrist_2_link" />
        <child link="ur_wrist_3_link" />
        <origin rpy="1.570796326589793 3.141592653589793 3.141592653589793" xyz="0 0.0823 -1.688001216681175e-11" />
        <axis xyz="0 0 1" />
        <limit effort="28.0" lower="-6.283185307179586" upper="6.283185307179586" velocity="3.141592653589793" />
        <dynamics damping="0" friction="0" />
    </joint>
    <!-- ROS-Industrial 'base' frame: base_link to UR 'Base' Coordinates transform -->
    <link name="ur_base" />
    <joint name="ur_base_link-base_fixed_joint" type="fixed">
        <!-- Note the rotation over Z of pi radians: as base_link is REP-103
           aligned (ie: has X+ forward, Y+ left and Z+ up), this is needed
           to correctly align 'base' with the 'Base' coordinate system of
           the UR controller.
      -->
        <origin rpy="0 0 3.141592653589793" xyz="0 0 0" />
        <parent link="ur_base_link" />
        <child link="ur_base" />
    </joint>
    <!-- ROS-Industrial 'flange' frame: attachment point for EEF models -->
    <link name="ur_flange" />
    <joint name="ur_wrist_3-flange" type="fixed">
        <parent link="ur_wrist_3_link" />
        <child link="ur_flange" />
        <origin rpy="0 -1.5707963267948966 -1.5707963267948966" xyz="0 0 0" />
    </joint>
    <!-- ROS-Industrial 'tool0' frame: all-zeros tool frame -->
    <link name="ur_tool0" />
    <joint name="ur_flange-tool0" type="fixed">
        <!-- default toolframe: X+ left, Y+ up, Z+ front -->
        <origin rpy="1.5707963267948966 0 1.5707963267948966" xyz="0 0 0" />
        <parent link="ur_flange" />
        <child link="ur_tool0" />
    </joint>
    <link name="box">
        <inertial>
            <origin rpy="0 0 0" xyz="-1.7293E-17 -5.5511E-17 0" />
            <mass value="216.68" />
            <inertia ixx="10.433" ixy="1.0023E-16" ixz="-6.9389E-16" iyy="15.422" iyz="4.2281E-16" izz="15.325" />
        </inertial>
        <visual>
            <origin rpy="0 0 0" xyz="0 0 0" />
            <geometry>
                <mesh filename="package://butler_robot/meshes/controlbox/box.STL" />
            </geometry>
            <material name="">
                <color rgba="1 1 1 1" />
            </material>
        </visual>
        <collision>
            <origin rpy="0 0 0" xyz="0 0 0" />
            <geometry>
                <mesh filename="package://butler_robot/meshes/controlbox/box.STL" />
            </geometry>
        </collision>
    </link>
    <link name="fh_logo1">
        <inertial>
            <origin rpy="0 0 0" xyz="0.40603 0.0005 -0.25853" />
            <mass value="0.044034" />
            <inertia ixx="3.6585E-05" ixy="2.9823E-16" ixz="-4.8032E-06" iyy="0.0013174" iyz="-5.2743E-17" izz="0.0012808" />
        </inertial>
        <visual>
            <origin rpy="0 0 0" xyz="0 0 0" />
            <geometry>
                <mesh filename="package://butler_robot/meshes/controlbox/fh_logo1.STL" />
            </geometry>
            <material name="">
                <color rgba="0.44706 0.47059 0.47843 1" />
            </material>
        </visual>
        <collision>
            <origin rpy="0 0 0" xyz="0 0 0" />
            <geometry>
                <mesh filename="package://butler_robot/meshes/controlbox/fh_logo1.STL" />
            </geometry>
        </collision>
    </link>
    <joint name="J_fh_logo1" type="fixed">
        <origin rpy="3.1416 -0.00044255 0" xyz="-0.40777 -0.27 -0.25281" />
        <parent link="box" />
        <child link="fh_logo1" />
        <axis xyz="0 0 0" />
    </joint>
    <link name="fh_logo2">
        <inertial>
            <origin rpy="0 0 0" xyz="0.2786 0.0005 -0.15603" />
            <mass value="0.022958" />
            <inertia ixx="2.0457E-05" ixy="2.4145E-19" ixz="1.4086E-06" iyy="0.00016849" iyz="-1.4001E-18" izz="0.00014804" />
        </inertial>
        <visual>
            <origin rpy="0 0 0" xyz="0 0 0" />
            <geometry>
                <mesh filename="package://butler_robot/meshes/controlbox/fh_logo2.STL" />
            </geometry>
            <material name="">
                <color rgba="0 0.39216 0.61176 1" />
            </material>
        </visual>
        <collision>
            <origin rpy="0 0 0" xyz="0 0 0" />
            <geometry>
                <mesh filename="package://butler_robot/meshes/controlbox/fh_logo2.STL" />
            </geometry>
        </collision>
    </link>
    <joint name="J_fh_logo2" type="fixed">
        <origin rpy="0 0 0" xyz="0 0 0" />
        <parent link="fh_logo1" />
        <child link="fh_logo2" />
        <axis xyz="0 0 0" />
    </joint>
    <link name="fh_logo3">
        <inertial>
            <origin rpy="0 0 0" xyz="0.19316 0.0005 -0.35769" />
            <mass value="0.015783" />
            <inertia ixx="1.3546E-05" ixy="5.4357E-20" ixz="1.6197E-06" iyy="6.4207E-05" iyz="2.5038E-19" izz="5.0664E-05" />
        </inertial>
        <visual>
            <origin rpy="0 0 0" xyz="0 0 0" />
            <geometry>
                <mesh filename="package://butler_robot/meshes/controlbox/fh_logo3.STL" />
            </geometry>
            <material name="">
                <color rgba="0.5451 0.70196 0.11373 1" />
            </material>
        </visual>
        <collision>
            <origin rpy="0 0 0" xyz="0 0 0" />
            <geometry>
                <mesh filename="package://butler_robot/meshes/controlbox/fh_logo3.STL" />
            </geometry>
        </collision>
    </link>
    <joint name="J_fh_logo3" type="fixed">
        <origin rpy="0 0 0" xyz="0 0 0" />
        <parent link="fh_logo2" />
        <child link="fh_logo3" />
        <axis xyz="0 0 0" />
    </joint>
    <link name="fh_logo4">
        <inertial>
            <origin rpy="0 0 0" xyz="0.40603 0.0005 -0.25853" />
            <mass value="0.044034" />
            <inertia ixx="3.6585E-05" ixy="2.9834E-16" ixz="-4.8032E-06" iyy="0.0013174" iyz="-5.2742E-17" izz="0.0012808" />
        </inertial>
        <visual>
            <origin rpy="0 0 0" xyz="0 0 0" />
            <geometry>
                <mesh filename="package://butler_robot/meshes/controlbox/fh_logo4.STL" />
            </geometry>
            <material name="">
                <color rgba="0.44706 0.47059 0.47843 1" />
            </material>
        </visual>
        <collision>
            <origin rpy="0 0 0" xyz="0 0 0" />
            <geometry>
                <mesh filename="package://butler_robot/meshes/controlbox/fh_logo4.STL" />
            </geometry>
        </collision>
    </link>
    <joint name="J_fh_logo4" type="fixed">
        <origin rpy="0 0.0008851 3.1416" xyz="0.81554 -0.54 0.00036092" />
        <parent link="fh_logo3" />
        <child link="fh_logo4" />
        <axis xyz="0 0 0" />
    </joint>
    <link name="fh_logo5">
        <inertial>
            <origin rpy="0 0 0" xyz="0.19316 0.0005 -0.35769" />
            <mass value="0.015783" />
            <inertia ixx="1.3546E-05" ixy="5.357E-20" ixz="1.6197E-06" iyy="6.4207E-05" iyz="2.4976E-19" izz="5.0664E-05" />
        </inertial>
        <visual>
            <origin rpy="0 0 0" xyz="0 0 0" />
            <geometry>
                <mesh filename="package://butler_robot/meshes/controlbox/fh_logo5.STL" />
            </geometry>
            <material name="">
                <color rgba="0.5451 0.70196 0.11373 1" />
            </material>
        </visual>
        <collision>
            <origin rpy="0 0 0" xyz="0 0 0" />
            <geometry>
                <mesh filename="package://butler_robot/meshes/controlbox/fh_logo5.STL" />
            </geometry>
        </collision>
    </link>
    <joint name="J_fh_logo5" type="fixed">
        <origin rpy="0 0 0" xyz="0 0 0" />
        <parent link="fh_logo4" />
        <child link="fh_logo5" />
        <axis xyz="0 0 0" />
    </joint>
    <link name="fh_logo6">
        <inertial>
            <origin rpy="0 0 0" xyz="0.2786 0.0005 -0.15603" />
            <mass value="0.022958" />
            <inertia ixx="2.0457E-05" ixy="2.5577E-19" ixz="1.4086E-06" iyy="0.00016849" iyz="-1.4007E-18" izz="0.00014804" />
        </inertial>
        <visual>
            <origin rpy="0 0 0" xyz="0 0 0" />
            <geometry>
                <mesh filename="package://butler_robot/meshes/controlbox/fh_logo6.STL" />
            </geometry>
            <material name="">
                <color rgba="0 0.39216 0.61176 1" />
            </material>
        </visual>
        <collision>
            <origin rpy="0 0 0" xyz="0 0 0" />
            <geometry>
                <mesh filename="package://butler_robot/meshes/controlbox/fh_logo6.STL" />
            </geometry>
        </collision>
    </link>
    <joint name="J_fh_logo6" type="fixed">
        <origin rpy="0 0 0" xyz="0 0 0" />
        <parent link="fh_logo5" />
        <child link="fh_logo6" />
        <axis xyz="0 0 0" />
    </joint>
    <gazebo reference="box">
        <material>Gazebo/White</material>
    </gazebo>
    <gazebo reference="fh_logo1">
        <material>Gazebo/Grey</material>
    </gazebo>
    <gazebo reference="fh_logo2">
        <material>Gazebo/Blue</material>
    </gazebo>
    <gazebo reference="fh_logo3">
        <material>Gazebo/Green</material>
    </gazebo>
    <gazebo reference="fh_logo4">
        <material>Gazebo/Grey</material>
    </gazebo>
    <gazebo reference="fh_logo5">
        <material>Gazebo/Blue</material>
    </gazebo>
    <gazebo reference="fh_logo6">
        <material>Gazebo/Green</material>
    </gazebo>
    <link name="robotiq_85_base_link">
        <inertial>
            <origin rpy="0 0 0" xyz="0.00021987 -2.3546E-10 0.030163" />
            <mass value="0.30915" />
            <inertia ixx="0.00028972" ixy="-5.7879E-10" ixz="-1.8543E-06" iyy="0.00030737" iyz="1.682E-12" izz="0.00019914" />
        </inertial>
        <visual>
            <origin rpy="0 0 0" xyz="0 0 0" />
            <geometry>
                <mesh filename="package://butler_robot/meshes/gripper/robotiq_85_base_link_fine.STL" />
            </geometry>
            <material name="">
                <color rgba="0.1 0.1 0.1 1" />
            </material>
        </visual>
        <collision>
            <origin rpy="0 0 0" xyz="0 0 0" />
            <geometry>
                <mesh filename="package://butler_robot/meshes/gripper/robotiq_85_base_link_coarse.STL" />
            </geometry>
        </collision>
    </link>
    <link name="left_outer_knuckle">
        <inertial>
            <origin rpy="0 0 0" xyz="0.0178331863169983 3.68915177224286E-11 0.0021442477325704" />
            <mass value="0.00684838849434396" />
            <inertia ixx="2.66832029033166E-07" ixy="1.66142314639824E-15" ixz="1.45945633322873E-07" iyy="1.3889233257419E-06" iyz="2.82951161241588E-15" izz="1.26603336914415E-06" />
        </inertial>
        <visual>
            <origin rpy="0 0 0" xyz="0 0 0" />
            <geometry>
                <mesh filename="package://butler_robot/meshes/gripper/outer_knuckle_fine.STL" />
            </geometry>
            <material name="">
                <color rgba="0.1 0.1 0.1 1" />
            </material>
        </visual>
        <collision>
            <origin rpy="0 0 0" xyz="0 0 0" />
            <geometry>
                <mesh filename="package://butler_robot/meshes/gripper/outer_knuckle_coarse.STL" />
            </geometry>
        </collision>
    </link>
    <joint name="finger_joint" type="fixed">
        <origin rpy="0 0 0" xyz="0.0306011444260539 0 0.0627920162695395" />
        <parent link="robotiq_85_base_link" />
        <child link="left_outer_knuckle" />
        <axis xyz="0 -1 0" />
        <limit effort="1000" lower="0" upper="0.725" velocity="2.0" />
    </joint>
    <link name="left_outer_finger">
        <inertial>
            <origin rpy="0 0 0" xyz="0.00131451599174296 2.88942057994543E-15 0.0215404163180413" />
            <mass value="0.0273093985570947" />
            <inertia ixx="8.51629628283022E-06" ixy="2.58174336207405E-19" ixz="3.83829504344079E-07" iyy="6.9133328065108E-06" iyz="-7.58589926143789E-19" izz="2.25006832221981E-06" />
        </inertial>
        <visual>
            <origin rpy="0 0 0" xyz="0 0 0" />
            <geometry>
                <mesh filename="package://butler_robot/meshes/gripper/outer_finger_fine.STL" />
            </geometry>
            <material name="">
                <color rgba="0.1 0.1 0.1 1" />
            </material>
        </visual>
        <collision>
            <origin rpy="0 0 0" xyz="0 0 0" />
            <geometry>
                <mesh filename="package://butler_robot/meshes/gripper/outer_finger_coarse.STL" />
            </geometry>
        </collision>
    </link>
    <joint name="left_outer_finger_joint" type="fixed">
        <origin rpy="0 0 0" xyz="0.0316910442266543 0 -0.00193396375724605" />
        <parent link="left_outer_knuckle" />
        <child link="left_outer_finger" />
        <axis xyz="0 -1 0" />
    </joint>
    <link name="left_inner_knuckle">
        <inertial>
            <origin rpy="0 0 0" xyz="0.017097546626628 -3.93808524389535E-10 0.0224918438201868" />
            <mass value="0.0110930853895903" />
            <inertia ixx="4.23392770691541E-06" ixy="5.748978936968E-15" ixz="1.78855677119788E-06" iyy="3.96548790524392E-06" iyz="1.05464666369669E-14" izz="3.24068002883007E-06" />
        </inertial>
        <visual>
            <origin rpy="0 0 0" xyz="0 0 0" />
            <geometry>
                <mesh filename="package://butler_robot/meshes/gripper/inner_knuckle_fine.STL" />
            </geometry>
            <material name="">
                <color rgba="0.1 0.1 0.1 1" />
            </material>
        </visual>
        <collision>
            <origin rpy="0 0 0" xyz="0 0 0" />
            <geometry>
                <mesh filename="package://butler_robot/meshes/gripper/inner_knuckle_coarse.STL" />
            </geometry>
        </collision>
    </link>
    <joint name="left_inner_knuckle_joint" type="fixed">
        <origin rpy="0 0 0" xyz="0.0127000000001501 0 0.0693074999999639" />
        <parent link="robotiq_85_base_link" />
        <child link="left_inner_knuckle" />
        <axis xyz="0 -1 0" />
        <limit effort="1000" lower="0" upper="0.8757" velocity="2.0" />
        <mimic joint="finger_joint" multiplier="1" offset="0" />
    </joint>
    <link name="left_inner_finger">
        <inertial>
            <origin rpy="0 0 0" xyz="0.0060275613594574 -6.29183141465421E-15 0.00669925693133241" />
            <mass value="0.00724255346165745" />
            <inertia ixx="1.47824274053603E-06" ixy="-3.94884463570303E-19" ixz="-3.45268847648622E-07" iyy="1.70064480838395E-06" iyz="3.5059838910097E-19" izz="4.77151336838364E-07" />
        </inertial>
        <visual>
            <origin rpy="0 0 0" xyz="0 0 0" />
            <geometry>
                <mesh filename="package://butler_robot/meshes/gripper/inner_finger_fine.STL" />
            </geometry>
            <material name="">
                <color rgba="0.1 0.1 0.1 1" />
            </material>
        </visual>
        <collision>
            <origin rpy="0 0 0" xyz="0 0 0" />
            <geometry>
                <mesh filename="package://butler_robot/meshes/gripper/inner_finger_coarse.STL" />
            </geometry>
        </collision>
    </link>
    <joint name="left_inner_finger_joint" type="fixed">
        <origin rpy="0 0 0" xyz="0.034585310861294 0 0.0454970193817975" />
        <parent link="left_inner_knuckle" />
        <child link="left_inner_finger" />
        <axis xyz="0 -1 0" />
        <limit effort="1000" lower="0" upper="0.8757" velocity="2.0" />
        <mimic joint="finger_joint" multiplier="-1" offset="0" />
    </joint>
    <link name="right_inner_knuckle">
        <inertial>
            <origin rpy="0 0 0" xyz="0.0168606186773776 3.93808471820465E-10 0.0226699950793434" />
            <mass value="0.0110930853895903" />
            <inertia ixx="4.27134775939882E-06" ixy="-8.53568456728898E-15" ixz="1.77774229944246E-06" iyy="3.96548790524392E-06" iyz="-8.45108024914164E-15" izz="3.20325997634666E-06" />
        </inertial>
        <visual>
            <origin rpy="0 0 0" xyz="0 0 0" />
            <geometry>
                <mesh filename="package://butler_robot/meshes/gripper/inner_knuckle_fine.STL" />
            </geometry>
            <material name="">
                <color rgba="0.1 0.1 0.1 1" />
            </material>
        </visual>
        <collision>
            <origin rpy="0 0 0" xyz="0 0 0" />
            <geometry>
                <mesh filename="package://butler_robot/meshes/gripper/inner_knuckle_coarse.STL" />
            </geometry>
        </collision>
    </link>
    <joint name="right_inner_knuckle_joint" type="fixed">
        <origin rpy="0 0 3.14159265358979" xyz="-0.0126999999998499 0 0.0693075000000361" />
        <parent link="robotiq_85_base_link" />
        <child link="right_inner_knuckle" />
        <axis xyz="0 1 0" />
        <limit effort="1000" lower="0" upper="0.8757" velocity="2.0" />
        <mimic joint="finger_joint" multiplier="-1" offset="0" />
    </joint>
    <link name="right_inner_finger">
        <inertial>
            <origin rpy="0 0 0" xyz="0.00602756228812038 -6.47284509480176E-15 0.00669925609578108" />
            <mass value="0.00724255346165744" />
            <inertia ixx="1.47824283625957E-06" ixy="-3.95952064019123E-19" ixz="-3.45268708875543E-07" iyy="1.70064480838394E-06" iyz="3.55286507960029E-19" izz="4.77151241114822E-07" />
        </inertial>
        <visual>
            <origin rpy="0 0 0" xyz="0 0 0" />
            <geometry>
                <mesh filename="package://butler_robot/meshes/gripper/inner_finger_fine.STL" />
            </geometry>
            <material name="">
                <color rgba="0.1 0.1 0.1 1" />
            </material>
        </visual>
        <collision>
            <origin rpy="0 0 0" xyz="0 0 0" />
            <geometry>
                <mesh filename="package://butler_robot/meshes/gripper/inner_finger_coarse.STL" />
            </geometry>
        </collision>
    </link>
    <joint name="right_inner_finger_joint" type="fixed">
        <origin rpy="0 0 0" xyz="0.0341060475457406 0 0.0458573878541688" />
        <parent link="right_inner_knuckle" />
        <child link="right_inner_finger" />
        <axis xyz="0 1 0" />
        <limit effort="1000" lower="0" upper="0.8757" velocity="2.0" />
        <mimic joint="finger_joint" multiplier="1" offset="0" />
    </joint>
    <link name="right_outer_knuckle">
        <inertial>
            <origin rpy="0 0 0" xyz="0.0178097074051638 3.60493211424024E-11 0.00233123458346721" />
            <mass value="0.00684838849401352" />
            <inertia ixx="2.70004361573169E-07" ixy="1.59579467624491E-15" ixz="1.56396493788199E-07" iyy="1.38892332558312E-06" iyz="2.82357800318817E-15" izz="1.26286103637978E-06" />
        </inertial>
        <visual>
            <origin rpy="0 0 0" xyz="0 0 0" />
            <geometry>
                <mesh filename="package://butler_robot/meshes/gripper/outer_knuckle_fine.STL" />
            </geometry>
            <material name="">
                <color rgba="0.1 0.1 0.1 1" />
            </material>
        </visual>
        <collision>
            <origin rpy="0 0 0" xyz="0 0 0" />
            <geometry>
                <mesh filename="package://butler_robot/meshes/gripper/outer_knuckle_coarse.STL" />
            </geometry>
        </collision>
    </link>
    <joint name="right_outer_knuckle_joint" type="fixed">
        <origin rpy="0 0 3.14159265358979" xyz="-0.0306011444258893 0 0.0627920162695395" />
        <parent link="robotiq_85_base_link" />
        <child link="right_outer_knuckle" />
        <axis xyz="0 1 0" />
        <limit effort="1000" lower="0" upper="0.8757" velocity="2.0" />
        <mimic joint="finger_joint" multiplier="-1" offset="0" />
    </joint>
    <link name="right_outer_finger">
        <inertial>
            <origin rpy="0 0 0" xyz="0.00108844269639009 -2.611488350845E-15 0.0215530225245502" />
            <mass value="0.0273093985570947" />
            <inertia ixx="8.52366028592721E-06" ixy="3.41683380899422E-19" ixz="3.18003675694284E-07" iyy="6.91333280651081E-06" iyz="7.37726682706417E-19" izz="2.24270431912283E-06" />
        </inertial>
        <visual>
            <origin rpy="0 0 0" xyz="0 0 0" />
            <geometry>
                <mesh filename="package://butler_robot/meshes/gripper/outer_finger_fine.STL" />
            </geometry>
            <material name="">
                <color rgba="0.1 0.1 0.1 1" />
            </material>
        </visual>
        <collision>
            <origin rpy="0 0 0" xyz="0 0 0" />
            <geometry>
                <mesh filename="package://butler_robot/meshes/gripper/outer_finger_coarse.STL" />
            </geometry>
        </collision>
    </link>
    <joint name="right_outer_finger_joint" type="fixed">
        <origin rpy="0 0 0" xyz="0.0317095909367246 0 -0.0016013564954687" />
        <parent link="right_outer_knuckle" />
        <child link="right_outer_finger" />
        <axis xyz="0 1 0" />
    </joint>
    <gazebo reference="robotiq_85_base_link">
        <material>Gazebo/Black</material>
    </gazebo>
    <gazebo reference="left_inner_knuckle">
        <material>Gazebo/Black</material>
    </gazebo>
    <gazebo reference="left_outer_knuckle">
        <material>Gazebo/Black</material>
    </gazebo>
    <gazebo reference="left_inner_finger">
        <material>Gazebo/Black</material>
    </gazebo>
    <gazebo reference="left_outer_finger">
        <material>Gazebo/Black</material>
    </gazebo>
    <gazebo reference="right_inner_knuckle">
        <material>Gazebo/Black</material>
    </gazebo>
    <gazebo reference="right_outer_knuckle">
        <material>Gazebo/Black</material>
    </gazebo>
    <gazebo reference="right_inner_finger">
        <material>Gazebo/Black</material>
    </gazebo>
    <gazebo reference="right_outer_finger">
        <material>Gazebo/Black</material>
    </gazebo>
    <!-- World Frame link -->
    <link name="world" />
    <!-- Connection UR to planning frame world -->
    <joint name="urFixedJoint" type="fixed">
        <parent link="base_link" />
        <child link="ur_base_link" />
        <origin rpy="0 0 0" xyz="0.25 -0.0125 0.892" />
    </joint>
    <!-- Connection MiR to planning frame world where UR is connected -->
    <joint name="compJoint" type="fixed">
        <origin rpy="0 0 0" xyz="0.153 -0.0325 0.892" />
        <!-- Caluculations: from base_footprint to surface 0.153 = 0.038 + 0.115; - ; 0.892 = 0.352 + 0.54-->
        <!--<origin xyz="0.093 -0.0125 0.892" rpy="0 0 0" />-->
        <parent link="base_link" />
        <child link="world" />
    </joint>
    <!-- Connection controlbox to MiR -->
    <joint name="boxJoint" type="fixed">
        <origin rpy="0 0 0" xyz="0.038 0 0.622" />
        <parent link="base_link" />
        <child link="box" />
    </joint>
    <!-- Connection UR to EEF -->
    <joint name="eef_fixed_joint" type="fixed">
        <parent link="ur_wrist_3_link" />
        <child link="robotiq_85_base_link" />
        <!--origin xyz="0.0 0.0823  0.0" rpy="${pi/2.0} 0.0 ${pi/2.0}" /-->
        <!-- 0.0823 = wrist_3_length -->
        <origin rpy="0.0 0.0 0.0" xyz="0.0 0.0  0.0" />
    </joint>
    <link name="tcp" />
    <joint name="tcp_gripper_joint" type="fixed">
        <parent link="ur_flange" />
        <child link="tcp" />
        <!-- <origin xyz="0.085 0.0 0.0" rpy="0.0 0.0 0.0" /> -->
        <origin rpy="0.0 0.0 0.0" xyz="0.18 0.0 0.0" />
    </joint>
    <!-- Camera plugin for gazebo -->
    <joint name="camera_joint" type="fixed">
        <parent link="tcp" />
        <child link="camera_link" />
        <origin rpy="-1.5708 0 -1.5708" xyz="0 0 0" />
    </joint>
    <link name="camera_link">
        <!-- <collision>
      <origin xyz="0 0 0" rpy="0 0 0" />
      <geometry>
        <box size="0.05 0.05 0.05" />
      </geometry>
    </collision>

    <visual>
      <origin xyz="0 0 0" rpy="0 0 0" />
      <geometry>
        <box size="0.05 0.05 0.05" />
      </geometry>
    </visual>

    <inertial>
      <mass value="1e-5" />
      <origin xyz="0 0 0" rpy="0 0 0" />
      <inertia ixx="1e-6" ixy="0" ixz="0" iyy="1e-6" iyz="0" izz="1e-6" />
    </inertial> -->
    </link>
    <!-- camera -->
    <gazebo reference="tcp">
        <sensor name="ee_camera" type="camera">
            <update_rate>30.0</update_rate>
            <camera name="head">
                <horizontal_fov>1.20428</horizontal_fov>
                <vertical_fov />
                <image>
                    <width>1920</width>
                    <height>1080</height>
                    <format>R8G8B8</format>
                </image>
                <clip>
                    <near>0.02</near>
                    <far>300</far>
                </clip>
                <noise>
                    <type>gaussian</type>
                    <!-- Noise is sampled independently per pixel on each frame.
               That pixel's noise value is added to each of its color
               channels, which at that point lie in the range [0,1]. -->
                    <mean>0.0</mean>
                    <stddev>0.007</stddev>
                </noise>
            </camera>
            <plugin filename="libgazebo_ros_camera.so" name="camera_controller">
                <alwaysOn>true</alwaysOn>
                <updateRate>0.0</updateRate>
                <cameraName>butler/ee_camera</cameraName>
                <imageTopicName>image_raw</imageTopicName>
                <cameraInfoTopicName>camera_info</cameraInfoTopicName>
                <frameName>camera_link</frameName>
                <hackBaseline>0.02</hackBaseline>
                <distortionK1>0.0</distortionK1>
                <distortionK2>0.0</distortionK2>
                <distortionK3>0.0</distortionK3>
                <distortionT1>0.0</distortionT1>
                <distortionT2>0.0</distortionT2>
            </plugin>
        </sensor>
    </gazebo>
    <transmission name="trans_fl_caster_rotation_joint">
        <type>transmission_interface/SimpleTransmission</type>
        <joint name="fl_caster_rotation_joint">
            <hardwareInterface>hardware_interface/EffortJointInterface</hardwareInterface>
        </joint>
        <actuator name="fl_caster_rotation_joint_motor">
            <hardwareInterface>hardware_interface/EffortJointInterface</hardwareInterface>
            <mechanicalReduction>1</mechanicalReduction>
        </actuator>
    </transmission>
    <transmission name="trans_fl_caster_wheel_joint">
        <type>transmission_interface/SimpleTransmission</type>
        <joint name="fl_caster_wheel_joint">
            <hardwareInterface>hardware_interface/EffortJointInterface</hardwareInterface>
        </joint>
        <actuator name="fl_caster_wheel_joint_motor">
            <hardwareInterface>hardware_interface/EffortJointInterface</hardwareInterface>
            <mechanicalReduction>1</mechanicalReduction>
        </actuator>
    </transmission>
    <transmission name="trans_fr_caster_rotation_joint">
        <type>transmission_interface/SimpleTransmission</type>
        <joint name="fr_caster_rotation_joint">
            <hardwareInterface>hardware_interface/EffortJointInterface</hardwareInterface>
        </joint>
        <actuator name="fr_caster_rotation_joint_motor">
            <hardwareInterface>hardware_interface/EffortJointInterface</hardwareInterface>
            <mechanicalReduction>1</mechanicalReduction>
        </actuator>
    </transmission>
    <transmission name="trans_fr_caster_wheel_joint">
        <type>transmission_interface/SimpleTransmission</type>
        <joint name="fr_caster_wheel_joint">
            <hardwareInterface>hardware_interface/EffortJointInterface</hardwareInterface>
        </joint>
        <actuator name="fr_caster_wheel_joint_motor">
            <hardwareInterface>hardware_interface/EffortJointInterface</hardwareInterface>
            <mechanicalReduction>1</mechanicalReduction>
        </actuator>
    </transmission>
    <transmission name="trans_bl_caster_rotation_joint">
        <type>transmission_interface/SimpleTransmission</type>
        <joint name="bl_caster_rotation_joint">
            <hardwareInterface>hardware_interface/EffortJointInterface</hardwareInterface>
        </joint>
        <actuator name="bl_caster_rotation_joint_motor">
            <hardwareInterface>hardware_interface/EffortJointInterface</hardwareInterface>
            <mechanicalReduction>1</mechanicalReduction>
        </actuator>
    </transmission>
    <transmission name="trans_bl_caster_wheel_joint">
        <type>transmission_interface/SimpleTransmission</type>
        <joint name="bl_caster_wheel_joint">
            <hardwareInterface>hardware_interface/EffortJointInterface</hardwareInterface>
        </joint>
        <actuator name="bl_caster_wheel_joint_motor">
            <hardwareInterface>hardware_interface/EffortJointInterface</hardwareInterface>
            <mechanicalReduction>1</mechanicalReduction>
        </actuator>
    </transmission>
    <transmission name="trans_br_caster_rotation_joint">
        <type>transmission_interface/SimpleTransmission</type>
        <joint name="br_caster_rotation_joint">
            <hardwareInterface>hardware_interface/EffortJointInterface</hardwareInterface>
        </joint>
        <actuator name="br_caster_rotation_joint_motor">
            <hardwareInterface>hardware_interface/EffortJointInterface</hardwareInterface>
            <mechanicalReduction>1</mechanicalReduction>
        </actuator>
    </transmission>
    <transmission name="trans_br_caster_wheel_joint">
        <type>transmission_interface/SimpleTransmission</type>
        <joint name="br_caster_wheel_joint">
            <hardwareInterface>hardware_interface/EffortJointInterface</hardwareInterface>
        </joint>
        <actuator name="br_caster_wheel_joint_motor">
            <hardwareInterface>hardware_interface/EffortJointInterface</hardwareInterface>
            <mechanicalReduction>1</mechanicalReduction>
        </actuator>
    </transmission>
</robot>

